Traceback (most recent call last):
  File "/Users/amalss/Documents/PhD/coursework/eess_website/.venv/lib/python3.13/site-packages/jupyter_core/utils/__init__.py", line 154, in wrapped
    asyncio.get_running_loop()
    ~~~~~~~~~~~~~~~~~~~~~~~~^^
RuntimeError: no running event loop

During handling of the above exception, another exception occurred:

Traceback (most recent call last):
  File "/Users/amalss/Documents/PhD/coursework/eess_website/.venv/lib/python3.13/site-packages/jupyter_cache/executors/utils.py", line 58, in single_nb_execution
    executenb(
    ~~~~~~~~~^
        nb,
        ^^^
    ...<4 lines>...
        **kwargs,
        ^^^^^^^^^
    )
    ^
  File "/Users/amalss/Documents/PhD/coursework/eess_website/.venv/lib/python3.13/site-packages/nbclient/client.py", line 1319, in execute
    return NotebookClient(nb=nb, resources=resources, km=km, **kwargs).execute()
           ~~~~~~~~~~~~~~~~~~~~~~~~~~~~~~~~~~~~~~~~~~~~~~~~~~~~~~~~~~~~~~~~~~~^^
  File "/Users/amalss/Documents/PhD/coursework/eess_website/.venv/lib/python3.13/site-packages/jupyter_core/utils/__init__.py", line 158, in wrapped
    return loop.run_until_complete(inner)
           ~~~~~~~~~~~~~~~~~~~~~~~^^^^^^^
  File "/opt/homebrew/Cellar/python@3.13/3.13.3/Frameworks/Python.framework/Versions/3.13/lib/python3.13/asyncio/base_events.py", line 719, in run_until_complete
    return future.result()
           ~~~~~~~~~~~~~^^
  File "/Users/amalss/Documents/PhD/coursework/eess_website/.venv/lib/python3.13/site-packages/nbclient/client.py", line 709, in async_execute
    await self.async_execute_cell(
        cell, index, execution_count=self.code_cells_executed + 1
    )
  File "/Users/amalss/Documents/PhD/coursework/eess_website/.venv/lib/python3.13/site-packages/nbclient/client.py", line 1062, in async_execute_cell
    await self._check_raise_for_error(cell, cell_index, exec_reply)
  File "/Users/amalss/Documents/PhD/coursework/eess_website/.venv/lib/python3.13/site-packages/nbclient/client.py", line 918, in _check_raise_for_error
    raise CellExecutionError.from_cell_and_msg(cell, exec_reply_content)
nbclient.exceptions.CellExecutionError: An error occurred while executing the following cell:
------------------

### Capacitor

A capacitor stores electrical energy as charge stored in the capacitor.
$$
\begin{align*}
Q &= CV \\
I = \frac{dQ}{dt} &= C \frac{dV}{dt}\\
\quad V(t) &= \frac{1}{C} \int I(t) \, dt
\end{align*}
$$

### Inductor

An inductor stores electrical energy in a magnetic field.
$$
V = L \frac{dI}{dt}, \quad I(t) = \frac{1}{L} \int V(t) \, dt
$$


### Voltage Source

A voltage source maintains a prescribed voltage difference independent of the current drawn, $V(t) = V_{\text{s}}$

### Current Source

A current source maintains a prescribed current independent of the voltage across it. $I(t) = I_{\text{s}}$


------------------


  [36mCell[39m[36m [39m[32mIn[1][39m[32m, line 3[39m
[31m    [39m[31mA capacitor stores electrical energy as charge stored in the capacitor.[39m
      ^
[31mSyntaxError[39m[31m:[39m invalid syntax


